Workbook

Sheet scenario_properties
B1: selectable_ruler_quantity | C1: year | D1: month
A2: first | B2: 12 | C2: 188 | D2: 11
A3: second | B3: 12 | C3: 193 | D3: 11
A4: third | B4: 9 | C4: 200 | D4: 11
A5: fourth | B5: 11 | C5: 207 | D5: 11
A6: fifth | B6: 5 | C6: 214 | D6: 11
A7: sixth | B7: 5 | C7: 219 | D7: 11

Sheet faction_info
A1: scenario | B1: faction_code | C1: color_pattern | D1: advisor | E1: ruler
A2: first | B2: 0 | C2: 3 | D2: 33 | E2: 0
A3: first | B3: 1 | C3: 6 | D3: -1 | E3: 1
A4: first | B4: 2 | C4: 10 | D4: 54 | E4: 2
A5: first | B5: 3 | C5: 1 | D5: 20 | E5: 3
A6: first | B6: 4 | C6: 4 | D6: -1 | E6: 4
A7: first | B7: 5 | C7: 5 | D7: -1 | E7: 5
A8: first | B8: 6 | C8: 11 | D8: -1 | E8: 6
A9: first | B9: 7 | C9: 8 | D9: 42 | E9: 7
A10: first | B10: 8 | C10: 0 | D10: 46 | E10: 8
A11: first | B11: 9 | C11: 15 | D11: -1 | E11: 9
A12: first | B12: 10 | C12: 2 | D12: -1 | E12: 10
A13: first | B13: 11 | C13: 14 | D13: -1 | E13: 11
... A97: sixth | B97: 15 | C97: 7 | D97: -1 | E97: -1

Sheet province_stats
A1: scenario | B1: province1 | C1: approval | D1: flood | E1: food | F1: gold | G1: horses | H1: land | I1: merchant | J1: population | K1: faction
A2: first | B2: 1 | C2: 5 | D2: 5 | E2: 20 | F2: 100 | G2: 5 | H2: 10 | I2: 0 | J2: 650 | K2: 255
A3: first | B3: 2 | C3: 5 | D3: 5 | E3: 20 | F3: 100 | G3: 5 | H3: 10 | I3: 0 | J3: 700 | K3: 255
A4: first | B4: 3 | C4: 35 | D4: 30 | E4: 250 | F4: 1000 | G4: 10 | H4: 55 | I4: 0 | J4: 1000 | K4: 9
A5: first | B5: 4 | C5: 55 | D5: 30 | E5: 250 | F5: 1000 | G5: 10 | H5: 50 | I5: 0 | J5: 1000 | K5: 1
A6: first | B6: 5 | C6: 15 | D6: 0 | E6: 20 | F6: 100 | G6: 5 | H6: 25 | I6: 0 | J6: 700 | K6: 255
A7: first | B7: 6 | C7: 50 | D7: 50 | E7: 700 | F7: 1000 | G7: 15 | H7: 50 | I7: 0 | J7: 5000 | K7: 3
A8: first | B8: 7 | C8: 55 | D8: 50 | E8: 300 | F8: 1000 | G8: 15 | H8: 65 | I8: 0 | J8: 1200 | K8: 11
A9: first | B9: 8 | C9: 65 | D9: 50 | E9: 250 | F9: 1000 | G9: 10 | H9: 65 | I9: 0 | J9: 800 | K9: 12
A10: first | B10: 9 | C10: 60 | D10: 30 | E10: 400 | F10: 1000 | G10: 20 | H10: 60 | I10: 0 | J10: 3500 | K10: 0
A11: first | B11: 10 | C11: 45 | D11: 50 | E11: 500 | F11: 1000 | G11: 30 | H11: 65 | I11: 1 | J11: 8000 | K11: 8
A12: first | B12: 11 | C12: 35 | D12: 35 | E12: 250 | F12: 500 | G12: 15 | H12: 45 | I12: 0 | J12: 4500 | K12: 8
A13: first | B13: 12 | C13: 40 | D13: 30 | E13: 250 | F13: 500 | G13: 20 | H13: 45 | I13: 1 | J13: 2500 | K13: 8
... A247: sixth | B247: 41 | C247: 5 | D247: 5 | E247: 20 | F247: 100 | G247: 0 | H247: 15 | I247: 0 | J247: 800 | K247: 255

Sheet portrait_palette_codes
A1: portrait_code | B1: palette_code
A2: 1 | B2: 0
A3: 2 | B3: 0
A4: 3 | B4: 3
A5: 4 | B5: 0
A6: 5 | B6: 1
A7: 6 | B7: 1
A8: 7 | B8: 0
A9: 8 | B9: 3
A10: 9 | B10: 0
A11: 10 | B11: 1
A12: 11 | B12: 0
A13: 12 | B13: 0
... A2001: 2000 | B2001: 2

Sheet officer_stats
B1: officer_name | C1: officer_number | D1: portrait_code | E1: intel | F1: war | G1: charm | H1: duty | I1: virtue | J1: ambition | K1: compatibility | L1: family | M1: birth_year_plus_one | N1: active_date | O1: autojoin
B2: =IF(INDEX(officer_names!$D$1:$D$2000, ROW(), 1)<>"",INDEX(officer_names!$D$1:$D$2000, ROW(), 1),"") -> Cao Cao | C2: 0 | D2: 103 | E2: 95 | F2: 91 | G2: 95 | H2: 60 | I2: 65 | J2: 99 | K2: 1 | L2: 1 | M2: 155 | N2: 255 | O2: 255
B3: =IF(INDEX(officer_names!$D$1:$D$2000, ROW(), 1)<>"",INDEX(officer_names!$D$1:$D$2000, ROW(), 1),"") -> Liu Bei | C3: 1 | D3: 161 | E3: 85 | F3: 70 | G3: 99 | H3: 100 | I3: 100 | J3: 85 | K3: 50 | L3: 2 | M3: 161 | N3: 255 | O3: 255
B4: =IF(INDEX(officer_names!$D$1:$D$2000, ROW(), 1)<>"",INDEX(officer_names!$D$1:$D$2000, ROW(), 1),"") -> Sun Jian | C4: 2 | D4: 1 | E4: 87 | F4: 90 | G4: 89 | H4: 60 | I4: 75 | J4: 90 | K4: 100 | L4: 4 | M4: 156 | N4: 255 | O4: 255
B5: =IF(INDEX(officer_names!$D$1:$D$2000, ROW(), 1)<>"",INDEX(officer_names!$D$1:$D$2000, ROW(), 1),"") -> Yuan Shao | C5: 3 | D5: 3 | E5: 70 | F5: 81 | G5: 70 | H5: 40 | I5: 25 | J5: 80 | K5: 40 | L5: 8 | M5: 145 | N5: 255 | O5: 255
B6: =IF(INDEX(officer_names!$D$1:$D$2000, ROW(), 1)<>"",INDEX(officer_names!$D$1:$D$2000, ROW(), 1),"") -> Yuan Shu | C6: 4 | D6: 74 | E6: 69 | F6: 80 | G6: 50 | H6: 40 | I6: 43 | J6: 81 | K6: 75 | L6: 16 | M6: 154 | N6: 255 | O6: 255
B7: =IF(INDEX(officer_names!$D$1:$D$2000, ROW(), 1)<>"",INDEX(officer_names!$D$1:$D$2000, ROW(), 1),"") -> Ma Teng | C7: 5 | D7: 140 | E7: 54 | F7: 95 | G7: 87 | H7: 88 | I7: 89 | J7: 86 | K7: 45 | L7: 32 | M7: 156 | N7: 255 | O7: 255
B8: =IF(INDEX(officer_names!$D$1:$D$2000, ROW(), 1)<>"",INDEX(officer_names!$D$1:$D$2000, ROW(), 1),"") -> Liu Yan | C8: 6 | D8: 156 | E8: 85 | F8: 45 | G8: 90 | H8: 83 | I8: 89 | J8: 30 | K8: 75 | L8: 64 | M8: 137 | N8: 255 | O8: 255
B9: =IF(INDEX(officer_names!$D$1:$D$2000, ROW(), 1)<>"",INDEX(officer_names!$D$1:$D$2000, ROW(), 1),"") -> Liu Biao | C9: 7 | D9: 160 | E9: 74 | F9: 73 | G9: 68 | H9: 80 | I9: 55 | J9: 25 | K9: 30 | L9: 128 | M9: 142 | N9: 255 | O9: 255
B10: =IF(INDEX(officer_names!$D$1:$D$2000, ROW(), 1)<>"",INDEX(officer_names!$D$1:$D$2000, ROW(), 1),"") -> Dong Zhuo | C10: 8 | D10: 134 | E10: 55 | F10: 90 | G10: 44 | H10: 40 | I10: 34 | J10: 95 | K10: 60 | L10: 256 | M10: 139 | N10: 255 | O10: 255
B11: =IF(INDEX(officer_names!$D$1:$D$2000, ROW(), 1)<>"",INDEX(officer_names!$D$1:$D$2000, ROW(), 1),"") -> Gongsun Zan | C11: 9 | D11: 64 | E11: 70 | F11: 75 | G11: 72 | H11: 79 | I11: 73 | J11: 69 | K11: 60 | L11: 512 | M11: 153 | N11: 255 | O11: 255
B12: =IF(INDEX(officer_names!$D$1:$D$2000, ROW(), 1)<>"",INDEX(officer_names!$D$1:$D$2000, ROW(), 1),"") -> Tao Quian | C12: 10 | D12: 132 | E12: 62 | F12: 51 | G12: 78 | H12: 77 | I12: 59 | J12: 50 | K12: 60 | L12: 0 | M12: 132 | N12: 255 | O12: 255
B13: =IF(INDEX(officer_names!$D$1:$D$2000, ROW(), 1)<>"",INDEX(officer_names!$D$1:$D$2000, ROW(), 1),"") -> Hain Fu | C13: 11 | D13: 40 | E13: 53 | F13: 51 | G13: 50 | H13: 48 | I13: 55 | J13: 56 | K13: 90 | L13: 0 | M13: 149 | N13: 255 | O13: 255
... B353: =IF(INDEX(officer_names!$D$1:$D$2000, ROW(), 1)<>"",INDEX(officer_names!$D$1:$D$2000, ROW(), 1),"") -> Sun Liang | C353: 351 | D353: 171 | E353: 55 | F353: 28 | G353: 86 | H353: 86 | I353: 51 | J353: 90 | K353: 100 | L353: 4 | M353: 243 | N353: 255 | O353: 108
B354: =IF(INDEX(officer_names!$D$1:$D$2000, ROW(), 1)<>"",INDEX(officer_names!$D$1:$D$2000, ROW(), 1),"")
B355: =IF(INDEX(officer_names!$D$1:$D$2000, ROW(), 1)<>"",INDEX(officer_names!$D$1:$D$2000, ROW(), 1),"")
B356: =IF(INDEX(officer_names!$D$1:$D$2000, ROW(), 1)<>"",INDEX(officer_names!$D$1:$D$2000, ROW(), 1),"")
B357: =IF(INDEX(officer_names!$D$1:$D$2000, ROW(), 1)<>"",INDEX(officer_names!$D$1:$D$2000, ROW(), 1),"")
B358: =IF(INDEX(officer_names!$D$1:$D$2000, ROW(), 1)<>"",INDEX(officer_names!$D$1:$D$2000, ROW(), 1),"")
B359: =IF(INDEX(officer_names!$D$1:$D$2000, ROW(), 1)<>"",INDEX(officer_names!$D$1:$D$2000, ROW(), 1),"")
B360: =IF(INDEX(officer_names!$D$1:$D$2000, ROW(), 1)<>"",INDEX(officer_names!$D$1:$D$2000, ROW(), 1),"")
B361: =IF(INDEX(officer_names!$D$1:$D$2000, ROW(), 1)<>"",INDEX(officer_names!$D$1:$D$2000, ROW(), 1),"")
B362: =IF(INDEX(officer_names!$D$1:$D$2000, ROW(), 1)<>"",INDEX(officer_names!$D$1:$D$2000, ROW(), 1),"")
B363: =IF(INDEX(officer_names!$D$1:$D$2000, ROW(), 1)<>"",INDEX(officer_names!$D$1:$D$2000, ROW(), 1),"")
B364: =IF(INDEX(officer_names!$D$1:$D$2000, ROW(), 1)<>"",INDEX(officer_names!$D$1:$D$2000, ROW(), 1),"")
B365: =IF(INDEX(officer_names!$D$1:$D$2000, ROW(), 1)<>"",INDEX(officer_names!$D$1:$D$2000, ROW(), 1),"")
... B2001: =IF(INDEX(officer_names!$D$1:$D$2000, ROW(), 1)<>"",INDEX(officer_names!$D$1:$D$2000, ROW(), 1),"") -> #VALUE!

Sheet officer_loyalties
B1: officer_name | C1: officer_number | D1: first | E1: second | F1: third | G1: fourth | H1: fifth | I1: sixth
B2: =IF(INDEX(officer_names!$D$1:$D$2000, ROW(), 1)<>"",INDEX(officer_names!$D$1:$D$2000, ROW(), 1),"") -> Cao Cao | C2: 0 | D2: 0 | E2: 100 | F2: 100 | G2: 0 | H2: 0 | I2: 255
B3: =IF(INDEX(officer_names!$D$1:$D$2000, ROW(), 1)<>"",INDEX(officer_names!$D$1:$D$2000, ROW(), 1),"") -> Liu Bei | C3: 1 | D3: 100 | E3: 100 | F3: 100 | G3: 0 | H3: 0 | I3: 100
B4: =IF(INDEX(officer_names!$D$1:$D$2000, ROW(), 1)<>"",INDEX(officer_names!$D$1:$D$2000, ROW(), 1),"") -> Sun Jian | C4: 2 | D4: 100 | E4: 255 | F4: 255 | G4: 255 | H4: 255 | I4: 255
B5: =IF(INDEX(officer_names!$D$1:$D$2000, ROW(), 1)<>"",INDEX(officer_names!$D$1:$D$2000, ROW(), 1),"") -> Yuan Shao | C5: 3 | D5: 0 | E5: 100 | F5: 100 | G5: 255 | H5: 255 | I5: 255
B6: =IF(INDEX(officer_names!$D$1:$D$2000, ROW(), 1)<>"",INDEX(officer_names!$D$1:$D$2000, ROW(), 1),"") -> Yuan Shu | C6: 4 | D6: 100 | E6: 100 | F6: 255 | G6: 255 | H6: 255 | I6: 255
B7: =IF(INDEX(officer_names!$D$1:$D$2000, ROW(), 1)<>"",INDEX(officer_names!$D$1:$D$2000, ROW(), 1),"") -> Ma Teng | C7: 5 | D7: 0 | E7: 100 | F7: 100 | G7: 0 | H7: 255 | I7: 255
B8: =IF(INDEX(officer_names!$D$1:$D$2000, ROW(), 1)<>"",INDEX(officer_names!$D$1:$D$2000, ROW(), 1),"") -> Liu Yan | C8: 6 | D8: 0 | E8: 255 | F8: 255 | G8: 255 | H8: 255 | I8: 255
B9: =IF(INDEX(officer_names!$D$1:$D$2000, ROW(), 1)<>"",INDEX(officer_names!$D$1:$D$2000, ROW(), 1),"") -> Liu Biao | C9: 7 | D9: 0 | E9: 100 | F9: 100 | G9: 255 | H9: 255 | I9: 255
B10: =IF(INDEX(officer_names!$D$1:$D$2000, ROW(), 1)<>"",INDEX(officer_names!$D$1:$D$2000, ROW(), 1),"") -> Dong Zhuo | C10: 8 | D10: 0 | E10: 255 | F10: 255 | G10: 255 | H10: 255 | I10: 255
B11: =IF(INDEX(officer_names!$D$1:$D$2000, ROW(), 1)<>"",INDEX(officer_names!$D$1:$D$2000, ROW(), 1),"") -> Gongsun Zan | C11: 9 | D11: 0 | E11: 100 | F11: 255 | G11: 255 | H11: 255 | I11: 255
B12: =IF(INDEX(officer_names!$D$1:$D$2000, ROW(), 1)<>"",INDEX(officer_names!$D$1:$D$2000, ROW(), 1),"") -> Tao Quian | C12: 10 | D12: 0 | E12: 255 | F12: 255 | G12: 255 | H12: 255 | I12: 255
B13: =IF(INDEX(officer_names!$D$1:$D$2000, ROW(), 1)<>"",INDEX(officer_names!$D$1:$D$2000, ROW(), 1),"") -> Hain Fu | C13: 11 | D13: 0 | E13: 255 | F13: 255 | G13: 255 | H13: 255 | I13: 255
... B353: =IF(INDEX(officer_names!$D$1:$D$2000, ROW(), 1)<>"",INDEX(officer_names!$D$1:$D$2000, ROW(), 1),"") -> Sun Liang | C353: 351 | D353: 255 | E353: 255 | F353: 255 | G353: 255 | H353: 255 | I353: 255
B354: =IF(INDEX(officer_names!$D$1:$D$2000, ROW(), 1)<>"",INDEX(officer_names!$D$1:$D$2000, ROW(), 1),"")
B355: =IF(INDEX(officer_names!$D$1:$D$2000, ROW(), 1)<>"",INDEX(officer_names!$D$1:$D$2000, ROW(), 1),"")
B356: =IF(INDEX(officer_names!$D$1:$D$2000, ROW(), 1)<>"",INDEX(officer_names!$D$1:$D$2000, ROW(), 1),"")
B357: =IF(INDEX(officer_names!$D$1:$D$2000, ROW(), 1)<>"",INDEX(officer_names!$D$1:$D$2000, ROW(), 1),"")
B358: =IF(INDEX(officer_names!$D$1:$D$2000, ROW(), 1)<>"",INDEX(officer_names!$D$1:$D$2000, ROW(), 1),"")
B359: =IF(INDEX(officer_names!$D$1:$D$2000, ROW(), 1)<>"",INDEX(officer_names!$D$1:$D$2000, ROW(), 1),"")
B360: =IF(INDEX(officer_names!$D$1:$D$2000, ROW(), 1)<>"",INDEX(officer_names!$D$1:$D$2000, ROW(), 1),"")
B361: =IF(INDEX(officer_names!$D$1:$D$2000, ROW(), 1)<>"",INDEX(officer_names!$D$1:$D$2000, ROW(), 1),"")
B362: =IF(INDEX(officer_names!$D$1:$D$2000, ROW(), 1)<>"",INDEX(officer_names!$D$1:$D$2000, ROW(), 1),"")
B363: =IF(INDEX(officer_names!$D$1:$D$2000, ROW(), 1)<>"",INDEX(officer_names!$D$1:$D$2000, ROW(), 1),"")
B364: =IF(INDEX(officer_names!$D$1:$D$2000, ROW(), 1)<>"",INDEX(officer_names!$D$1:$D$2000, ROW(), 1),"")
B365: =IF(INDEX(officer_names!$D$1:$D$2000, ROW(), 1)<>"",INDEX(officer_names!$D$1:$D$2000, ROW(), 1),"")
... B2001: =IF(INDEX(officer_names!$D$1:$D$2000, ROW(), 1)<>"",INDEX(officer_names!$D$1:$D$2000, ROW(), 1),"") -> #VALUE!

Sheet officer_provinces
B1: officer_name | C1: officer_number | D1: first | E1: second | F1: third | G1: fourth | H1: fifth | I1: sixth
B2: =IF(INDEX(officer_names!$D$1:$D$2000, ROW(), 1)<>"",INDEX(officer_names!$D$1:$D$2000, ROW(), 1),"") -> Cao Cao | C2: 0 | D2: 8 | E2: 9 | F2: 16 | G2: 16 | H2: 16 | I2: 255
B3: =IF(INDEX(officer_names!$D$1:$D$2000, ROW(), 1)<>"",INDEX(officer_names!$D$1:$D$2000, ROW(), 1),"") -> Liu Bei | C3: 1 | D3: 3 | E3: 15 | F3: 18 | G3: 18 | H3: 32 | I3: 32
B4: =IF(INDEX(officer_names!$D$1:$D$2000, ROW(), 1)<>"",INDEX(officer_names!$D$1:$D$2000, ROW(), 1),"") -> Sun Jian | C4: 2 | D4: 20 | E4: 255 | F4: 255 | G4: 255 | H4: 255 | I4: 255
B5: =IF(INDEX(officer_names!$D$1:$D$2000, ROW(), 1)<>"",INDEX(officer_names!$D$1:$D$2000, ROW(), 1),"") -> Yuan Shao | C5: 3 | D5: 5 | E5: 5 | F5: 5 | G5: 255 | H5: 255 | I5: 255
B6: =IF(INDEX(officer_names!$D$1:$D$2000, ROW(), 1)<>"",INDEX(officer_names!$D$1:$D$2000, ROW(), 1),"") -> Yuan Shu | C6: 4 | D6: 18 | E6: 16 | F6: 255 | G6: 255 | H6: 255 | I6: 255
B7: =IF(INDEX(officer_names!$D$1:$D$2000, ROW(), 1)<>"",INDEX(officer_names!$D$1:$D$2000, ROW(), 1),"") -> Ma Teng | C7: 5 | D7: 13 | E7: 13 | F7: 13 | G7: 14 | H7: 255 | I7: 255
B8: =IF(INDEX(officer_names!$D$1:$D$2000, ROW(), 1)<>"",INDEX(officer_names!$D$1:$D$2000, ROW(), 1),"") -> Liu Yan | C8: 6 | D8: 32 | E8: 255 | F8: 255 | G8: 255 | H8: 255 | I8: 255
B9: =IF(INDEX(officer_names!$D$1:$D$2000, ROW(), 1)<>"",INDEX(officer_names!$D$1:$D$2000, ROW(), 1),"") -> Liu Biao | C9: 7 | D9: 19 | E9: 19 | F9: 19 | G9: 255 | H9: 255 | I9: 255
B10: =IF(INDEX(officer_names!$D$1:$D$2000, ROW(), 1)<>"",INDEX(officer_names!$D$1:$D$2000, ROW(), 1),"") -> Dong Zhuo | C10: 8 | D10: 9 | E10: 255 | F10: 255 | G10: 255 | H10: 255 | I10: 255
B11: =IF(INDEX(officer_names!$D$1:$D$2000, ROW(), 1)<>"",INDEX(officer_names!$D$1:$D$2000, ROW(), 1),"") -> Gongsun Zan | C11: 9 | D11: 2 | E11: 2 | F11: 255 | G11: 255 | H11: 255 | I11: 255
B12: =IF(INDEX(officer_names!$D$1:$D$2000, ROW(), 1)<>"",INDEX(officer_names!$D$1:$D$2000, ROW(), 1),"") -> Tao Quian | C12: 10 | D12: 15 | E12: 255 | F12: 255 | G12: 255 | H12: 255 | I12: 255
B13: =IF(INDEX(officer_names!$D$1:$D$2000, ROW(), 1)<>"",INDEX(officer_names!$D$1:$D$2000, ROW(), 1),"") -> Hain Fu | C13: 11 | D13: 6 | E13: 255 | F13: 255 | G13: 255 | H13: 255 | I13: 255
... B353: =IF(INDEX(officer_names!$D$1:$D$2000, ROW(), 1)<>"",INDEX(officer_names!$D$1:$D$2000, ROW(), 1),"") -> Sun Liang | C353: 351 | D353: 20 | E353: 24 | F353: 23 | G353: 23 | H353: 23 | I353: 23
B354: =IF(INDEX(officer_names!$D$1:$D$2000, ROW(), 1)<>"",INDEX(officer_names!$D$1:$D$2000, ROW(), 1),"")
B355: =IF(INDEX(officer_names!$D$1:$D$2000, ROW(), 1)<>"",INDEX(officer_names!$D$1:$D$2000, ROW(), 1),"")
B356: =IF(INDEX(officer_names!$D$1:$D$2000, ROW(), 1)<>"",INDEX(officer_names!$D$1:$D$2000, ROW(), 1),"")
B357: =IF(INDEX(officer_names!$D$1:$D$2000, ROW(), 1)<>"",INDEX(officer_names!$D$1:$D$2000, ROW(), 1),"")
B358: =IF(INDEX(officer_names!$D$1:$D$2000, ROW(), 1)<>"",INDEX(officer_names!$D$1:$D$2000, ROW(), 1),"")
B359: =IF(INDEX(officer_names!$D$1:$D$2000, ROW(), 1)<>"",INDEX(officer_names!$D$1:$D$2000, ROW(), 1),"")
B360: =IF(INDEX(officer_names!$D$1:$D$2000, ROW(), 1)<>"",INDEX(officer_names!$D$1:$D$2000, ROW(), 1),"")
B361: =IF(INDEX(officer_names!$D$1:$D$2000, ROW(), 1)<>"",INDEX(officer_names!$D$1:$D$2000, ROW(), 1),"")
B362: =IF(INDEX(officer_names!$D$1:$D$2000, ROW(), 1)<>"",INDEX(officer_names!$D$1:$D$2000, ROW(), 1),"")
B363: =IF(INDEX(officer_names!$D$1:$D$2000, ROW(), 1)<>"",INDEX(officer_names!$D$1:$D$2000, ROW(), 1),"")
B364: =IF(INDEX(officer_names!$D$1:$D$2000, ROW(), 1)<>"",INDEX(officer_names!$D$1:$D$2000, ROW(), 1),"")
B365: =IF(INDEX(officer_names!$D$1:$D$2000, ROW(), 1)<>"",INDEX(officer_names!$D$1:$D$2000, ROW(), 1),"")
... B2001: =IF(INDEX(officer_names!$D$1:$D$2000, ROW(), 1)<>"",INDEX(officer_names!$D$1:$D$2000, ROW(), 1),"") -> #VALUE!

Sheet officer_names
C1: officer_number | D1: officer_name
C2: 0 | D2: Cao Cao
C3: 1 | D3: Liu Bei
C4: 2 | D4: Sun Jian
C5: 3 | D5: Yuan Shao
C6: 4 | D6: Yuan Shu
C7: 5 | D7: Ma Teng
C8: 6 | D8: Liu Yan
C9: 7 | D9: Liu Biao
C10: 8 | D10: Dong Zhuo
C11: 9 | D11: Gongsun Zan
C12: 10 | D12: Tao Quian
C13: 11 | D13: Hain Fu
... C353: 351 | D353: Sun Liang

Sheet later_first_scenario
A1: year | B1: sequence
A2: 190 | B2: 206; 185; 197; 182; 181; 341; 184; 153; 169; 198
A3: 191 | B3: 167; 162; 213; 165; 212; 168; 217; 207; 180
A4: 192 | B4: 215; 166; 199; 160; 191; 190; 179; 193; 196; 154; 194; 155; 214
A5: 193 | B5: 195; 177; 159; 211; 164; 178; 240; 172; 201; 188; 189; 176; 156
A6: 194 | B6: 216; 157; 209; 192; 170; 210; 219; 187; 152; 158; 208
A7: 195 | B7: 229; 251; 232; 278; 256; 239; 243; 225; 224; 161; 221; 238
A8: 196 | B8: 255
A9: 197 | B9: 248; 220
A10: 198 | B10: 265; 247; 227
A11: 199 | B11: 253; 264; 241
A12: 200 | B12: 223; 236; 237; 222; 226; 259; 228; 263; 262; 260; 230; 250; 245; 261; 231; 252
A13: 201 | B13: 234; 235; 249; 244; 266; 233
... A36: 255 | B36: 351

Sheet later_second_scenario
A1: year | B1: sequence
A2: 195 | B2: 239; 224; 232; 225; 251; 278; 238; 229; 256; 221; 243
A3: 196 | B3: 255
A4: 197 | B4: 220; 248
A5: 198 | B5: 227; 247; 265
A6: 199 | B6: 253; 241; 264
A7: 200 | B7: 237; 252; 263; 222; 231; 261; 226; 230; 245; 260; 228; 250; 262; 236; 223; 259
A8: 201 | B8: 234; 266; 249; 235; 233; 244
A9: 202 | B9: 281; 290; 286; 270; 273; 272; 269; 292; 293
A10: 203 | B10: 280; 277; 276
A11: 204 | B11: 283; 275
A12: 205 | B12: 279; 287; 274; 267; 285; 303
A13: 206 | B13: 294; 268
... A31: 255 | B31: 351

Sheet later_third_scenario
A1: year | B1: sequence
A2: 193 | B2: 177; 178
A3: 192 | B3: 215; 194
A4: 201 | B4: 295; 108; 266; 146
A5: 195 | B5: 278
A6: 191 | B6: 207
A7: 202 | B7: 273; 290; 272; 286; 269; 270; 292; 293; 281
A8: 203 | B8: 277; 276; 280
A9: 204 | B9: 275; 283
A10: 205 | B10: 279; 274; 287; 285; 303; 267
A11: 206 | B11: 268; 294
A12: 207 | B12: 271; 282; 296
A13: 208 | B13: 289; 288
... A29: 255 | B29: 351

Sheet later_fourth_scenario
A1: year | B1: sequence
A2: 193 | B2: 177
A3: 208 | B3: 103
A4: 205 | B4: 303
A5: 192 | B5: 215
A6: 209 | B6: 309; 324; 318; 307
A7: 210 | B7: 317; 314; 321; 320; 300; 305; 323
A8: 211 | B8: 302
A9: 214 | B9: 301; 310; 312
A10: 215 | B10: 163; 311; 328; 322
A11: 216 | B11: 336; 337; 334; 333; 340; 339
A12: 217 | B12: 338
A13: 218 | B13: 335
... A21: 255 | B21: 351

Sheet later_fifth_scenario
A1: year | B1: sequence
A2: 216 | B2: 339; 336; 334; 333; 337; 340
A3: 217 | B3: 338; 332
A4: 218 | B4: 335
A5: 220 | B5: 331; 329; 330
A6: 222 | B6: 344; 343; 342
A7: 223 | B7: 345
A8: 225 | B8: 346
A9: 226 | B9: 347
A10: 230 | B10: 349; 348
A11: 238 | B11: 350
A12: 255 | B12: 351

Sheet later_sixth_scenario
A1: year | B1: sequence
A2: 222 | B2: 342; 343; 344
A3: 223 | B3: 345
A4: 225 | B4: 346
A5: 226 | B5: 347
A6: 230 | B6: 348; 349
A7: 238 | B7: 350
A8: 255 | B8: 351

Sheet immediate_first_scenario
A1: province1 | B1: employment | C1: sequence
A2: 1 | B2: employed
B3: hidden
A4: 2 | B4: employed
B5: hidden
A6: 3 | B6: employed | C6: 9; 19
B7: hidden
A8: 4 | B8: employed | C8: 1; 40; 41
B9: hidden
A10: 5 | B10: employed
B11: hidden | C11: 57
A12: 6 | B12: employed | C12: 3; 20; 21; 22; 23; 24; 25; 26; 27; 28; 30; 31; 32; 92; 97; 100; 106
B13: hidden | C13: 85; 112; 116
A14: 7 | B14: employed | C14: 11; 29; 66; 111
B15: hidden
A16: 8 | B16: employed | C16: 12; 115; 125
B17: hidden
A18: 9 | B18: employed | C18: 0; 33; 34; 35; 36; 37; 38; 39; 45
B19: hidden | C19: 99; 118; 123; 135
A20: 10 | B20: employed | C20: 8; 46; 52; 77; 95; 110; 117; 129
B21: hidden | C21: 132; 133; 145
A22: 11 | B22: employed | C22: 15; 82; 109; 144; 146
B23: hidden
A24: 12 | B24: employed | C24: 16; 67; 93
B25: hidden | C25: 148
A26: 13 | B26: employed
B27: hidden
A28: 14 | B28: employed | C28: 5; 69; 84
B29: hidden | C29: 104
A30: 15 | B30: employed
B31: hidden | C31: 141
A32: 16 | B32: employed | C32: 10; 87; 88; 101; 113; 114
B33: hidden
A34: 17 | B34: employed
B35: hidden | C35: 80; 81; 134; 138; 140; 149
A36: 18 | B36: employed
B37: hidden | C37: 51; 126
A38: 19 | B38: employed | C38: 4; 43; 60; 83; 91; 103; 136; 137
B39: hidden | C39: 64
A40: 20 | B40: employed | C40: 7; 42; 44; 48; 50; 61; 65; 70; 71; 76; 86
...

Sheet immediate_second_scenario
A1: province1 | B1: employment | C1: sequence
A2: 1 | B2: employed
B3: hidden
A4: 2 | B4: employed
B5: hidden
A6: 3 | B6: employed | C6: 9; 182
B7: hidden
A8: 4 | B8: employed
B9: hidden
A10: 5 | B10: employed | C10: 151; 161
B11: hidden
A12: 6 | B12: employed | C12: 3; 20; 32; 23; 24; 25; 66; 111; 21; 100; 106
B13: hidden | C13: 181; 112
A14: 7 | B14: employed | C14: 22; 26; 27; 28; 240; 31; 30; 125; 92; 97
B15: hidden | C15: 116; 85
A16: 8 | B16: employed | C16: 12; 115
B17: hidden | C17: 196; 211
A18: 9 | B18: employed | C18: 52; 33; 156; 162; 171; 173; 174; 175; 145; 138; 186
B19: hidden | C19: 185
A20: 10 | B20: employed | C20: 0; 154; 155; 160; 99; 34; 36; 37; 165; 166
B21: hidden | C21: 169; 132; 179
A22: 11 | B22: employed | C22: 35; 38; 157; 164; 170; 45; 180; 39; 80; 81; 210
B23: hidden | C23: 135; 199; 201; 118; 212; 140; 149; 218; 134
A24: 12 | B24: employed | C24: 16; 46; 82; 144
B25: hidden | C25: 148
A26: 13 | B26: employed
B27: hidden | C27: 163
A28: 14 | B28: employed | C28: 5; 168; 176; 69; 104; 188; 84; 191; 192; 193; 198; 141; 217
B29: hidden | C29: 57
A30: 15 | B30: employed
B31: hidden
A32: 16 | B32: employed | C32: 1; 101; 114; 88; 87; 113; 40; 41
B33: hidden | C33: 187
A34: 17 | B34: employed | C34: 4; 43; 60; 91; 136
B35: hidden | C35: 64; 219
A36: 18 | B36: employed
B37: hidden | C37: 51; 167; 126
A38: 19 | B38: employed | C38: 83; 103; 137
B39: hidden | C39: 190; 208
A40: 20 | B40: employed | C40: 7; 42; 48; 50; 61; 70
...

Sheet immediate_third_scenario
A1: province1 | B1: employment | C1: sequence
A2: 1 | B2: employed | C2: 116
B3: hidden
A4: 2 | B4: employed | C4: 30
B5: hidden
A6: 3 | B6: employed | C6: 21; 26
B7: hidden
A8: 4 | B8: employed
B9: hidden
A10: 5 | B10: employed
B11: hidden
A12: 6 | B12: employed | C12: 3; 20; 32; 23; 111; 27; 240; 66; 31
B13: hidden | C13: 181; 112
A14: 7 | B14: employed | C14: 92; 28; 97
B15: hidden
A16: 8 | B16: employed | C16: 22; 24; 85; 242; 254
B17: hidden | C17: 196; 211
A18: 9 | B18: employed | C18: 36; 155; 149; 157; 161; 39; 12; 199; 140
B19: hidden | C19: 162; 185
A20: 10 | B20: employed | C20: 156; 165; 174; 80; 237; 134
B21: hidden | C21: 132; 46
A22: 11 | B22: employed | C22: 35; 170; 167; 180; 175; 210; 201; 135; 218
B23: hidden | C23: 133; 261; 118; 212
A24: 12 | B24: employed
B25: hidden
A26: 13 | B26: employed
B27: hidden
A28: 14 | B28: employed | C28: 5; 168; 176; 192; 69; 104; 188; 84; 191; 217
B29: hidden | C29: 57
A30: 15 | B30: employed | C30: 221; 198; 141; 193
B31: hidden
A32: 16 | B32: employed | C32: 34; 164; 235; 101; 38; 45; 246; 247; 257; 145; 81
B33: hidden
A34: 17 | B34: employed | C34: 0; 225; 160; 154; 232; 233; 99; 243; 245
B35: hidden | C35: 219
A36: 18 | B36: employed | C36: 56; 59; 126; 228; 105; 216; 250; 213; 256
B37: hidden | C37: 51; 208
A38: 19 | B38: employed | C38: 1; 40; 41; 182; 88; 114; 113; 239; 187; 179; 252
B39: hidden | C39: 190; 255; 103; 137
A40: 20 | B40: employed | C40: 7; 42; 44; 224; 48; 50; 61; 71; 70
...

Sheet immediate_fourth_scenario
A1: province1 | B1: employment | C1: sequence
A2: 1 | B2: employed | C2: 116
B3: hidden
A4: 2 | B4: employed | C4: 267; 218
B5: hidden
A6: 3 | B6: employed | C6: 211
B7: hidden
A8: 4 | B8: employed | C8: 199; 97
B9: hidden
A10: 5 | B10: employed | C10: 170; 201; 134; 149
B11: hidden
A12: 6 | B12: employed | C12: 46; 31; 85; 242
B13: hidden
A14: 7 | B14: employed | C14: 133; 165; 135; 140
B15: hidden
A16: 8 | B16: employed | C16: 35; 210; 157; 12; 28; 118; 254
B17: hidden | C17: 196
A18: 9 | B18: employed | C18: 233; 268; 257; 39; 180; 243
B19: hidden | C19: 162; 185
A20: 10 | B20: employed | C20: 38; 156; 71; 197; 190; 132; 80; 45
B21: hidden | C21: 146
A22: 11 | B22: employed | C22: 235; 161; 237; 155; 175; 245; 167
B23: hidden | C23: 261
A24: 12 | B24: employed | C24: 34; 111; 36; 275; 280; 81; 164; 212
B25: hidden
A26: 13 | B26: employed
B27: hidden | C27: 270
A28: 14 | B28: employed | C28: 168; 176; 191; 192; 69; 104; 188; 291; 217; 193
B29: hidden | C29: 57
A30: 15 | B30: employed | C30: 5; 198; 221; 84; 141
B31: hidden
A32: 16 | B32: employed
B33: hidden
A34: 17 | B34: employed | C34: 0; 225; 154; 232; 274; 276; 246; 281; 282; 139; 247
B35: hidden
A36: 18 | B36: employed | C36: 56; 59; 250; 272; 105; 216; 258; 230; 228
B37: hidden | C37: 51
A38: 19 | B38: employed | C38: 1; 255; 40; 182; 41; 88; 187; 252; 277; 114; 113; 283; 239; 179; 287; 290; 296
B39: hidden | C39: 178; 219; 137; 108; 292; 208
A40: 20 | B40: employed | C40: 266; 184
...

Sheet immediate_fifth_scenario
A1: province1 | B1: employment | C1: sequence
A2: 1 | B2: employed
B3: hidden
A4: 2 | B4: employed | C4: 134
B5: hidden | C5: 116
A6: 3 | B6: employed | C6: 211
B7: hidden
A8: 4 | B8: employed | C8: 45
B9: hidden
A10: 5 | B10: employed | C10: 199; 257
B11: hidden
A12: 6 | B12: employed | C12: 46
B13: hidden
A14: 7 | B14: employed | C14: 165
B15: hidden
A16: 8 | B16: employed | C16: 35; 157
B17: hidden | C17: 196
A18: 9 | B18: employed | C18: 81
B19: hidden | C19: 162; 185
A20: 10 | B20: employed | C20: 232; 190; 192; 170; 132; 80; 327
B21: hidden
A22: 11 | B22: employed | C22: 38; 71; 268; 180; 118; 175; 328
B23: hidden
A24: 12 | B24: employed | C24: 237; 233; 261; 280; 276
B25: hidden | C25: 57
A26: 13 | B26: employed | C26: 150
B27: hidden
A28: 14 | B28: employed | C28: 69
B29: hidden
A30: 15 | B30: employed
B31: hidden
A32: 16 | B32: employed | C32: 133; 140; 167; 243; 210
B33: hidden
A34: 17 | B34: employed | C34: 0; 225; 281; 274; 282; 161; 212; 245; 246; 124; 267
B35: hidden
A36: 18 | B36: employed | C36: 156; 235; 39; 135; 149; 218; 323; 326
B37: hidden
A38: 19 | B38: employed | C38: 40; 239; 108; 179; 296; 309; 312; 318
B39: hidden | C39: 103; 137
A40: 20 | B40: employed | C40: 113; 191; 303; 284; 277; 289; 314; 114; 119
...

Sheet immediate_sixth_scenario
A1: province1 | B1: employment | C1: sequence
A2: 1 | B2: employed
B3: hidden | C3: 116
A4: 2 | B4: employed | C4: 329
B5: hidden
A6: 3 | B6: employed | C6: 211
B7: hidden
A8: 4 | B8: employed | C8: 45
B9: hidden
A10: 5 | B10: employed | C10: 199; 257
B11: hidden
A12: 6 | B12: employed | C12: 190
B13: hidden
A14: 7 | B14: employed | C14: 165; 340
B15: hidden
A16: 8 | B16: employed | C16: 170; 157
B17: hidden | C17: 196
A18: 9 | B18: employed | C18: 133
B19: hidden | C19: 162; 185
A20: 10 | B20: employed | C20: 281; 225; 330; 46; 331; 332; 235; 246; 81; 326; 132
B21: hidden
A22: 11 | B22: employed | C22: 282; 180
B23: hidden
A24: 12 | B24: employed | C24: 237; 245; 164; 274; 233; 175
B25: hidden | C25: 339
A26: 13 | B26: employed | C26: 36; 111; 334; 80; 153; 69
B27: hidden
A28: 14 | B28: employed | C28: 150
B29: hidden
A30: 15 | B30: employed
B31: hidden
A32: 16 | B32: employed | C32: 267; 243; 210; 140; 167
B33: hidden
A34: 17 | B34: employed | C34: 38; 261; 118; 212; 218
B35: hidden
A36: 18 | B36: employed | C36: 156; 300; 135; 149; 327; 323
B37: hidden
A38: 19 | B38: employed | C38: 280; 161; 141; 201
B39: hidden | C39: 103; 137
A40: 20 | B40: employed | C40: 275; 163; 268; 71; 119; 328
...
